Workbook

Sheet Livro diário
B2: Data | C2: Descrição | D2: Valor | E2: Total
B3: 45261 | C3: Capital social | D3: 650000 | E3: =D3 -> 650000
C4: Banco | D4: 292500 | E4: =D4 -> 292500
C5: Caixa | D5: 162500 | E5: =D5 -> 162500
C6: Imóvel | D6: 97500 | E6: =D6 -> 97500
C7: Instalações | D7: 32500 | E7: =D7 -> 32500
C8: Móveis | D8: 52000 | E8: =D8 -> 52000
C9: Máquinas e equipamentos | D9: 13000 | E9: =D9 -> 13000
B10: 45262 | C10: Mercadoria/Estoque | D10: 350000 | E10: =D10 -> 350000
C11: Banco | D11: 245000 | E11: =D11 -> 245000
C12: Fornecedor | D12: 105000 | E12: =D12 -> 105000
B13: 45263 | C13: Obtenção de obras | D13: 25500 | E13: =D13 -> 25500
C14: Débito automático (Banco) | D14: 25500 | E14: =D14 -> 25500
B15: 45264 | C15: Suprimentos/Estoque | D15: 7500 | E15: =D15 -> 7500
C16: Débito automático (Banco) | D16: 7500 | E16: =D16 -> 7500
B17: 45265 | C17: Carro 01 | D17: 63000 | E17: =D17 -> 63000
C18: Carro 02 | D18: 63000 | E18: =D18 -> 63000
C19: Caixa | D19: 1000 | E19: =D19 -> 1000
C20: Banco | D20: 19000 | E20: =D20 -> 19000
C21: Duplicata a pagar | D21: 106000 | E21: =D21 -> 106000
B22: 45280 | C22: Venda de mercadoria | D22: 77000 | E22: =D22 -> 77000
C23: Caixa | D23: 26950 | E23: =D23 -> 26950
C24: Duplicata a receber | D24: 50050 | E24: =D24 -> 50050
B25: 45281 | C25: Venda de mercadoria | D25: 6000 | E25: =D25 -> 6000
C26: Caixa | D26: 6000 | E26: =D26 -> 6000
B27: 45282 | C27: Vendas a prazo | D27: 23600 | E27: =D27 -> 23600
C28: Boletos (banco) | D28: 23600 | E28: =D28 -> 23600
B29: 45283 | C29: Venda de mercadoria | D29: 15000 | E29: =D29 -> 15000
C30: Caixa | D30: 3000 | E30: =D30 -> 3000
C31: Duplicata a receber | D31: 12000 | E31: =D31 -> 12000
B32: 45284 | C32: Venda de mercadoria | D32: 165000 | E32: =D32 -> 165000
C33: Banco | D33: 75000 | E33: =D33 -> 75000
C34: Duplicata a receber | D34: 90000 | E34: =D34 -> 90000
B35: 45290 | C35: Pagamento de 70% (Banco) | D35: 74200 | E35: =D35 -> 74200
C36: Duplicata a pagar (05/12) | D36: 74200 | E36: =D36 -> 74200

Sheet Razonete
C2: Capital social (PL)
C3: D | D3: C
B4: 45261 | D4: 650000 | E4: x
B5: Total | C5: =SUM(C4) -> 0 | D5: =SUM(D4) -> 650000
C7: Banco (A)
C8: D | D8: C
B9: 45261 | C9: 292500 | E9: x
B10: 45262 | D10: 245000 | E10: x
B11: 45263 | D11: 25500 | E11: x
B12: 45264 | D12: 7500 | E12: x
B13: 45265 | D13: 19000 | E13: x
B14: 45282 | C14: 23600 | E14: x
B15: 45284 | C15: 75000 | E15: x
B16: 45290 | D16: 74200 | E16: x
B17: Total | C17: =SUM(C9:C16) -> 391100 | D17: =SUM(D9:D16) -> 371200
C19: Caixa (A)
C20: D | D20: C
B21: 45261 | C21: 162500 | E21: x
B22: 45265 | D22: 1000 | E22: x
B23: 45280 | C23: 26950 | E23: x
B24: 45281 | C24: 6000 | E24: x
B25: 45283 | C25: 3000 | E25: x
B26: Total | C26: =SUM(C21:C25) -> 198450 | D26: =SUM(D21:D25) -> 1000
C28: Imóvel (A)
C29: D | D29: C
B30: 45261 | C30: 97500 | E30: x
B31: Total | C31: =SUM(C30) -> 97500 | D31: =SUM(D30) -> 0
C33: Instalações (A)
C34: D | D34: C
B35: 45261 | C35: 32500 | E35: x
B36: Total | C36: =SUM(C35) -> 32500 | D36: =SUM(D35) -> 0
C38: Móvel (A)
C39: D | D39: C
B40: 45261 | C40: 52000 | E40: x
B41: Total | C41: =SUM(C40) -> 52000 | D41: =SUM(D40) -> 0
C43: Máquina e equipamento (A)
C44: D | D44: C
B45: 45261 | C45: 13000 | E45: x
B46: Total | C46: =SUM(C45) -> 13000 | D46: =SUM(D45) -> 0
C48: Mercadoria/Estoque (A)
...

Sheet Balancete
B3: Contas | C3: Natureza | D3: Débito | E3: Crédito | F3: Saldo
B4: =Razonete!C2 -> Capital social (PL) | C4: Credora | D4: =Razonete!C5 -> 0 | E4: =Razonete!D5 -> 650000 | F4: =E4-D4 -> 650000
B5: =Razonete!C7 -> Banco (A) | C5: Devedora | D5: =Razonete!C17 -> 391100 | E5: =Razonete!D17 -> 371200 | F5: =D5-E5 -> 19900
B6: =Razonete!C19 -> Caixa (A) | C6: Devedora | D6: =Razonete!C26 -> 198450 | E6: =Razonete!D26 -> 1000 | F6: =D6-E6 -> 197450
B7: =Razonete!C28 -> Imóvel (A) | C7: Devedora | D7: =Razonete!C31 -> 97500 | E7: =Razonete!D31 -> 0 | F7: =D7-E7 -> 97500
B8: =Razonete!C33 -> Instalações (A) | C8: Devedora | D8: =Razonete!C36 -> 32500 | E8: =Razonete!D36 -> 0 | F8: =D8-E8 -> 32500
B9: =Razonete!C38 -> Móvel (A) | C9: Devedora | D9: =Razonete!C41 -> 52000 | E9: =Razonete!D41 -> 0 | F9: =D9-E9 -> 52000
B10: =Razonete!C43 -> Máquina e equipamento (A) | C10: Devedora | D10: =Razonete!C46 -> 13000 | E10: =Razonete!D46 -> 0 | F10: =D10-E10 -> 13000
B11: =Razonete!C48 -> Mercadoria/Estoque (A) | C11: Devedora | D11: =Razonete!C51 -> 350000 | E11: =Razonete!D51 -> 0 | F11: =D11-E11 -> 350000
B12: =Razonete!C53 -> Duplicata a pagar (P) | C12: Credora | D12: =Razonete!C57 -> 74200 | E12: =Razonete!D57 -> 211000 | F12: =E12-D12 -> 136800
B13: =Razonete!C59 -> Obras - Arte - (A) | C13: Devedora | D13: =Razonete!C62 -> 25500 | E13: =Razonete!D62 -> 0 | F13: =D13-E13 -> 25500
B14: =Razonete!C64 -> Escritório, Limpeza e copa (P) | C14: Credora | D14: =Razonete!C67 -> 7500 | E14: =Razonete!D67 -> 0 | F14: =D14-E14 -> 7500
B15: =Razonete!C69 -> Carros (A) | C15: Devedora | D15: =Razonete!C72 -> 126000 | E15: =Razonete!D72 -> 0 | F15: =D15-E15 -> 126000
B16: =Razonete!C74 -> Vendas mercadoria (A) | C16: Devedora | D16: =Razonete!C81 -> 0 | E16: =Razonete!D81 -> 286600 | F16: =E16-D16 -> 286600
B17: =Razonete!C83 -> Duplicatas a receber (A) | C17: Devedora | D17: =Razonete!C88 -> 152050 | E17: =Razonete!D88 -> 0 | F17: =D17-E17 -> 152050
B18: - | C18: Total | D18: =SUM(D4:D17) -> 1519800 | E18: =SUM(E4:E17) -> 1519800 | F18: =D18-E18 -> 0

Sheet Balanço patrimonial
C3: ATIVO | F3: PASSIVO + PATRIMÔNIO LÍQUIDO
C4: ATIVO CIRCULANTE | F4: PASSIVO CIRCULANTE
C5: Caixa | D5: 197450 | F5: Duplicata a Pagar | G5: 136800
C6: Banco | D6: 19900 | F6: Escritório, Limpeza e Copa | G6: 7500
C7: Duplicatas a Receber | D7: 152050 | F7: Total Passivo Circulante | G7: =SUM(G5:G6) -> 144300
C8: Mercadoria/Estoque | D8: 350000
C9: Vendas Mercadoria | D9: 286600 | F9: PATRIMÔNIO LÍQUIDO
C10: Total Ativo Circulante | D10: =SUM(D5:D9) -> 1006000 | F10: Capital Social | G10: 650000
F11: Total Patrimônio Líquido | G11: =SUM(G10:G10) -> 650000
C12: ATIVO NÃO CIRCULANTE
C13: Imóvel | D13: 97500 | F13: TOTAL PASSIVO + PL | G13: =G7+G11 -> 794300
C14: Instalações | D14: 32500
C15: Móvel | D15: 52000
C16: Máquina e Equipamento | D16: 13000
C17: Obras - Arte | D17: 25500
C18: Carros | D18: 126000
C19: Total Ativo Não Circulante | D19: =SUM(D13:D18) -> 346500
C21: TOTAL DO ATIVO | D21: =D10+D19 -> 1352500
