Workbook

Sheet Razonete
C2: Capital Social (PL)
C3: D | D3: C
B4: 44928 | D4: 12000
B5: 44952 | D5: 5000
B6: Total | C6: =SUM(C4:C5) -> 0 | D6: =SUM(D4:D5) -> 17000
C8: Caixa (Ativo)
C9: D | D9: C
B10: 44928 | C10: 12000
B11: 44930 | D11: 2500
B12: 44931 | D12: 2000
B13: 44949 | D13: 1000
B14: 44952 | C14: 5000
B15: 44956 | D15: 8500
B16: Total | C16: =SUM(C10:C15) -> 17000 | D16: =SUM(D10:D15) -> 14000
C18: Bens Imóveis - Cia A - (Ativo)
C19: D | D19: C
B20: 44930 | C20: 5000
B21: Total | C21: =SUM(C20) -> 5000 | D21: =SUM(D20) -> 0
C23: Duplicatas a pagar (Passivo)
C24: D | D24: C
B25: 44930 | D25: 2500
B26: 44941 | D26: 4000
B27: 44949 | C27: 1000
B28: Total | C28: =SUM(C25:C27) -> 1000 | D28: =SUM(D25:D27) -> 6500
C30: Intalações (Ativo)
C31: D | D31: C
B32: 44931 | C32: 2000
B33: Total | C33: =SUM(C32) -> 2000 | D33: =SUM(D32) -> 0
C35: Equipamentos - M & Cia - (Ativo)
C36: D | D36: C
B37: 44941 | C37: 4000
B38: Total | C38: =SUM(C37) -> 4000 | D38: =SUM(D37) -> 0
C40: Empréstimo - Banco alfa - (Passivo)
C41: D | D41: C
B42: 44944 | D42: 10000
B43: Total | C43: =SUM(C42) -> 0 | D43: =SUM(D42) -> 10000
C45: Nota promissória
C46: D | D46: C
B47: 44944 | C47: 10000
B48: Total | C48: =SUM(C47) -> 10000 | D48: =SUM(D47) -> 0
...

Sheet Balancete
B2: Balancete de Verificação
B3: Contas | C3: Natureza | D3: Débito | E3: Crédito | F3: Saldo
B4: Capital Social | C4: PL | D4: =Razonete!C6 -> 0 | E4: =Razonete!D6 -> 17000 | F4: 17000
B5: Caixa | C5: Devedora | D5: =Razonete!C16 -> 17000 | E5: =Razonete!D16 -> 14000 | F5: 3000
B6: Bens Imóveis | C6: Devedora | D6: =Razonete!C21 -> 5000 | E6: =Razonete!D21 -> 0 | F6: 5000
B7: Duplicatas | C7: Credora | D7: =Razonete!C28 -> 1000 | E7: =Razonete!D28 -> 6500 | F7: 5500
B8: Instalações | C8: Devedora | D8: =Razonete!C33 -> 2000 | E8: =Razonete!D33 -> 0 | F8: 2000
B9: Equipamentos | C9: Devedora | D9: =Razonete!C38 -> 4000 | E9: =Razonete!D38 -> 0 | F9: 4000
B10: Empréstimo | C10: Credora | D10: =Razonete!C43 -> 0 | E10: =Razonete!D43 -> 10000 | F10: 10000
B11: Nota Promissória | C11: Devedora | D11: =Razonete!C48 -> 10000 | E11: =Razonete!D48 -> 0 | F11: 10000
B12: Peças | C12: Devedora | D12: =Razonete!C53 -> 8500 | E12: =Razonete!D53 -> 0 | F12: 8500
C13: Total | D13: =SUM(D4:D12) -> 47500 | E13: =SUM(E4:E12) -> 47500 | F13: -

Sheet Balanço Patrimonial
B2: Balanço Patrôminal
B3: Ativo | D3: Passivo
B4: Circulante | D4: Duplicadas a pagar | E4: =Balancete!F7 -> 5500
B5: Disponibilidade | D5: Empréstimo | E5: =Balancete!F10 -> 10000
B6: Caixa | C6: =Balancete!F5 -> 3000 | D6: Total do passivo | E6: =SUM(E4:E5) -> 15500
B7: Banco | C7: =Balancete!F11 -> 10000
B8: Total | C8: =SUM(C6:C7) -> 13000
B9: Não circulante | D9: Patrimônio líquido
B10: Imóvel | C10: =Balancete!F6 -> 5000 | D10: Capital Social | E10: =Balancete!F4 -> 17000
B11: Instalações | C11: =Balancete!F8 -> 2000
B12: Máquinas | C12: =Balancete!F9 -> 4000
B13: Peças | C13: =Balancete!F12 -> 8500
B14: Total | C14: =SUM(C10:C13) -> 19500
B15: Total do ativo | C15: =C8+C14 -> 32500 | D15: Balanço | E15: =E6+E10 -> 32500
